Workbook

Sheet Planilha1
AF2: horas | AG2: 8 | AH2: 9 | AI2: 10 | AJ2: 11 | AK2: 12 | AL2: 13 | AM2: 14 | AN2: 15 | AO2: 16 | AP2: 17 | AQ2: 18
D3: Dados Projeto | I3: TM | N3: Parede externa C | AA3: Janera
I4: TBS | J4: 32.2 | K4: Tm= | L4: =J4-(J5/2) -> 26.6 | N4: nomeclatura | O4: orientaçao | P4: compri. | Q4: Pé Direito | R4: Area total | S4: QNT | T4: Vão Janeira | U4: Area final | AA4: NOMEN | AB4: compr | AC4: Alt | AD4: AREA | AF4: norte | AG4: 6 | AH4: 5 | AI4: 5 | AJ4: 5 | AK4: 5 | AL4: 6 | AM4: 8 | AN4: 9 | AO4: 11 | AP4: 12 | AQ4: 13 | AT4: DTCTcorr - Pe1 | AW4: DTCTcorr - Pe2 | AZ4: DTCTcorr- Pe3 | BC4: DTCTcorr - Pe4
D5: Latitude | E5: 10.98 | F5: Sul | I5: AD | J5: 11.2 | N5: Pe1 | O5: Sul | P5: 53 | Q5: 2.7 | R5: =P5*Q5 -> 143.1 | S5: 6 | T5: =S5*AD5 -> 18 | U5: =R5-T5 -> 125.1 | AA5: J1 | AB5: 2 | AC5: 1.5 | AD5: =AB5*AC5 -> 3 | AF5: Leste | AG5: 7 | AH5: 8 | AI5: 9 | AJ5: 11 | AK5: 13 | AL5: 14 | AM5: 15 | AN5: 16 | AO5: 16 | AP5: 17 | AQ5: 17 | AT5: 1 | AU5: =(AG6+($AG$18))*1+(25.5-24)+(26.6-29.4) -> 2.2 | AW5: 1 | AX5: =(AG5+($AG$16))*1+(25.5-24)+(26.6-29.4) -> 5.2 | AZ5: 1 | BA5: =(AG7+($AG$17))*1+(25.5-24)+(26.6-29.4) -> 7.2 | BC5: 1 | BD5: =(AG4+($AG$18))*1+(25.5-24)+(26.6-29.4) -> 4.2
D6: Mês>Qt | E6: Out | N6: Pe2 | O6: Leste | P6: 22 | Q6: 2.7 | R6: =P6*Q6 -> 59.4 | S6: 6 | T6: =S6*AD5+1.5 -> 19.5 | U6: =R6-T6 -> 39.9 | AA6: J2 | AB6: 3 | AC6: 1.5 | AD6: =AB6*AC6 -> 4.5 | AF6: Sul | AG6: 4 | AH6: 4 | AI6: 4 | AJ6: 4 | AK6: 4 | AL6: 5 | AM6: 5 | AN6: 6 | AO6: 6 | AP6: 7 | AQ6: 8 | AT6: 2 | AU6: =(AH6+($AG$18))*1+(25.5-24)+(26.6-29.4) -> 2.2 | AW6: 2 | AX6: =(AH5+($AG$16))*1+(25.5-24)+(26.6-29.4) -> 6.2 | AZ6: 2 | BA6: =(AH7+($AG$17))*1+(25.5-24)+(26.6-29.4) -> 6.2 | BC6: 2 | BD6: =(AH4+($AG$18))*1+(25.5-24)+(26.6-29.4) -> 3.2
D7: k= | E7: 1 | N7: Pe3 | O7: Oeste | P7: 22 | Q7: 2.7 | R7: =P7*Q7 -> 59.4 | S7: 2 | T7: =S7*AD6 -> 9 | U7: =R7-T7 -> 50.4 | AF7: Oeste | AG7: 9 | AH7: 8 | AI7: 7 | AJ7: 7 | AK7: 7 | AL7: 7 | AM7: 7 | AN7: 8 | AO7: 9 | AP7: 11 | AQ7: 13 | AT7: 3 | AU7: =(AI6+($AG$18))*1+(25.5-24)+(26.6-29.4) -> 2.2 | AW7: 3 | AX7: =(AI5+($AG$16))*1+(25.5-24)+(26.6-29.4) -> 7.2 | AZ7: 3 | BA7: =(AI7+($AG$17))*1+(25.5-24)+(26.6-29.4) -> 5.2 | BC7: 3 | BD7: =(AI4+($AG$18))*1+(25.5-24)+(26.6-29.4) -> 3.2
N8: Pe4 | O8: Norte | P8: 53 | Q8: 2.7 | R8: =P8*Q8 -> 143.1 | S8: 7 | T8: =S8*AD5 -> 21 | U8: =R8-T8 -> 122.1 | AT8: 4 | AU8: =(AJ6+($AG$18))*1+(25.5-24)+(26.6-29.4) -> 2.2 | AW8: 4 | AX8: =(AJ5+($AG$16))*1+(25.5-24)+(26.6-29.4) -> 9.2 | AZ8: 4 | BA8: =(AJ7+($AG$17))*1+(25.5-24)+(26.6-29.4) -> 5.2 | BC8: 4 | BD8: =(AJ4+($AG$18))*1+(25.5-24)+(26.6-29.4) -> 3.2
D9: Parede U | E9: 1.56 | AT9: 5 | AU9: =(AJ6+($AG$18))*1+(25.5-24)+(26.6-29.4) -> 2.2 | AW9: 5 | AX9: =(AK5+($AG$16))*1+(25.5-24)+(26.6-29.4) -> 11.2 | AZ9: 5 | BA9: =(AK7+($AG$17))*1+(25.5-24)+(26.6-29.4) -> 5.2 | BC9: 5 | BD9: =(AK4+($AG$18))*1+(25.5-24)+(26.6-29.4) -> 3.2
AT10: 6 | AU10: =(AL6+($AG$18))*1+(25.5-24)+(26.6-29.4) -> 3.2 | AW10: 6 | AX10: =(AL5+($AG$16))*1+(25.5-24)+(26.6-29.4) -> 12.2 | AZ10: 6 | BA10: =(AL7+($AG$17))*1+(25.5-24)+(26.6-29.4) -> 5.2 | BC10: 6 | BD10: =(AL4+($AG$18))*1+(25.5-24)+(26.6-29.4) -> 4.2
D11: Teto U | E11: 0.727 | AL11: DTCTtab TETO | AO11: DTCTcorr TETO | AT11: 7 | AU11: =(AM6+($AG$18))*1+(25.5-24)+(26.6-29.4) -> 3.2 | AW11: 7 | AX11: =(AM5+($AG$16))*1+(25.5-24)+(26.6-29.4) -> 13.2 | AZ11: 7 | BA11: =(AM7+($AG$17))*1+(25.5-24)+(26.6-29.4) -> 5.2 | BC11: 7 | BD11: =(AM4+($AG$18))*1+(25.5-24)+(26.6-29.4) -> 6.2
N12: Parede externa C Pe1 | AL12: 8 | AM12: 11 | AO12: 8 | AP12: =(AM12+$E$5)*1+(25.5-24)+($L$4-29.4) -> 20.68 | AT12: 8 | AU12: =(AN6+($AG$18))*1+(25.5-24)+(26.6-29.4) -> 4.2 | AW12: 8 | AX12: =(AN5+($AG$16))*1+(25.5-24)+(26.6-29.4) -> 14.2 | AZ12: 8 | BA12: =(AN7+($AG$17))*1+(25.5-24)+(26.6-29.4) -> 6.2 | BC12: 8 | BD12: =(AN4+($AG$18))*1+(25.5-24)+(26.6-29.4) -> 7.2
N13: trecho | O13: orientaçao | P13: compri. | Q13: Pé Direito | R13: Area total | S13: QNT | T13: Vão Janeira | U13: Area final | AF13: Fator LM (Outubro / Lat. 16° S) | AL13: 9 | AM13: 11 | AN13: 1 | AO13: 9 | AP13: =(AM13+$E$5)*1+(25.5-24)+($L$4-29.4) -> 20.68 | AT13: 9 | AU13: =(AO6+($AG$18))*1+(25.5-24)+(26.6-29.4) -> 4.2 | AW13: 9 | AX13: =(AO5+($AG$16))*1+(25.5-24)+(26.6-29.4) -> 14.2 | AZ13: 9 | BA13: =(AO7+($AG$17))*1+(25.5-24)+(26.6-29.4) -> 7.2 | BC13: 9 | BD13: =(AO4+($AG$18))*1+(25.5-24)+(26.6-29.4) -> 9.2
N14: 5 | O14: Sul | P14: =N14 -> 5 | Q14: 2.7 | R14: =P14*Q14 -> 13.5 | S14: 0 | T14: =S14*AD12 -> 0 | U14: =R14-T14 -> 13.5 | AF14: Orientação Real da Parede (Hemisfério Sul) | AL14: 10 | AM14: 11 | AN14: 2 | AO14: 10 | AP14: =(AM14+$E$5)*1+(25.5-24)+($L$4-29.4) -> 20.68 | AT14: 10 | AU14: =(AP6+($AG$18))*1+(25.5-24)+(26.6-29.4) -> 5.2 | AW14: 10 | AX14: =(AP5+($AG$16))*1+(25.5-24)+(26.6-29.4) -> 15.2 | AZ14: 10 | BA14: =(AP7+($AG$17))*1+(25.5-24)+(26.6-29.4) -> 9.2 | BC14: 10 | BD14: =(AP4+($AG$18))*1+(25.5-24)+(26.6-29.4) -> 10.2
N15: 2 | P15: =N15 -> 2 | Q15: 2.7 | R15: =P15*Q15 -> 5.4 | S15: 0 | U15: =R15-T15 -> 5.4 | AF15: Norte (N) | AG15: -3,3 | AL15: 11 | AM15: 12 | AN15: 3 | AO15: 11 | AP15: =(AM15+$E$5)*1+(25.5-24)+($L$4-29.4) -> 21.68 | AT15: 11 | AU15: =(AQ6+($AG$18))*1+(25.5-24)+(26.6-29.4) -> 6.2 | AW15: 11 | AX15: =(AQ5+($AG$16))*1+(25.5-24)+(26.6-29.4) -> 15.2 | AZ15: 11 | BA15: =(AQ7+($AG$17))*1+(25.5-24)+(26.6-29.4) -> 11.2 | BC15: 11 | BD15: =(AQ4+($AG$18))*1+(25.5-24)+(26.6-29.4) -> 11.2
N16: 3 | P16: =N16 -> 3 | Q16: 2.7 | R16: =P16*Q16 -> 8.1 | S16: 1 | T16: =AD5 -> 3 | U16: =R16-T16 -> 5.1 | AF16: Leste (E) / Oeste (O) | AG16: -0.5 | AL16: 12 | AM16: 13 | AN16: 4 | AO16: 12 | AP16: =(AM16+$E$5)*1+(25.5-24)+($L$4-29.4) -> 22.68
N17: 3 | P17: =N17 -> 3 | Q17: 2.7 | R17: =P17*Q17 -> 8.1 | S17: 0 | U17: =R17-T17 -> 8.1 | AF17: Oste | AG17: -0.5 | AL17: 13 | AM17: 15 | AN17: 5 | AO17: 13 | AP17: =(AM17+$E$5)*1+(25.5-24)+($L$4-29.4) -> 24.68
N18: 4 | P18: =N18 -> 4 | Q18: 2.7 | R18: =P18*Q18 -> 10.8 | S18: 0 | T18: 0 | U18: =R18-T18 -> 10.8 | AF18: Sul (S) | AG18: -0.5 | AL18: 14 | AM18: 16 | AN18: 6 | AO18: 14 | AP18: =(AM18+$E$5)*1+(25.5-24)+($L$4-29.4) -> 25.68
AL19: 15 | AM19: 18 | AN19: 7 | AO19: 15 | AP19: =(AM19+$E$5)*1+(25.5-24)+($L$4-29.4) -> 27.68
N20: Parede externa C Pe2 | AL20: 16 | AM20: 19 | AN20: 8 | AO20: 16 | AP20: =(AM20+$E$5)*1+(25.5-24)+($L$4-29.4) -> 28.68
N21: trecho | O21: orientaçao | P21: compri. | Q21: Pé Direito | R21: Area total | S21: QNT | T21: Vão Janeira | U21: Area final | AL21: 17 | AM21: 20 | AN21: 9 | AO21: 17 | AP21: =(AM21+$E$5)*1+(25.5-24)+($L$4-29.4) -> 29.68
N22: 7 | O22: leste | P22: =N22 -> 7 | Q22: 2.7 | R22: =P22*Q22 -> 18.9 | S22: 2 | T22: =AD5*S22 -> 6 | U22: =R22-T22 -> 12.9 | AL22: 18 | AM22: 21 | AN22: 10 | AO22: 18 | AP22: =(AM22+$E$5)*1+(25.5-24)+($L$4-29.4) -> 30.68
N23: 7 | P23: =N23 -> 7 | Q23: 2.7 | R23: =P23*Q23 -> 18.9 | S23: 2 | T23: =AD5*S23 -> 6 | U23: =R23-T23 -> 12.9
N24: 3 | P24: =N24 -> 3 | Q24: 2.7 | R24: =P24*Q24 -> 8.1 | S24: 1 | T24: =S24*AD5 -> 3 | U24: =R24-T24 -> 5.1
N25: 5 | P25: =N25 -> 5 | Q25: 2.7 | R25: =P25*Q25 -> 13.5 | S25: 1 | T25: =S25*AD6 -> 4.5 | U25: =R25-T25 -> 9
N27: Parede externa C Pe3
N28: trecho | O28: orientaçao | P28: compri. | Q28: Pé Direito | R28: Area total | S28: QNT | T28: Vão Janeira | U28: Area final
N29: 8 | O29: Oeste | P29: =N29 -> 8 | Q29: 2.7 | R29: =P29*Q29 -> 21.6 | T29: =AD12*S29 -> 0 | U29: =R29-T29 -> 21.6
N30: 3 | P30: =N30 -> 3 | Q30: 2.7 | R30: =P30*Q30 -> 8.1 | T30: =AD12*S30 -> 0 | U30: =R30-T30 -> 8.1
N31: 3 | P31: =N31 -> 3 | Q31: 2.7 | R31: =P31*Q31 -> 8.1 | T31: =S31*AD12 -> 0 | U31: =R31-T31 -> 8.1
N32: 8 | P32: =N32 -> 8 | Q32: 2.7 | R32: =P32*Q32 -> 21.6 | S32: 2 | T32: =S32*AD6 -> 9 | U32: =R32-T32 -> 12.6
N34: Parede externa C Pe4
N35: trecho | O35: orientaçao | P35: compri. | Q35: Pé Direito | R35: Area total | S35: QNT | T35: Vão Janeira | U35: Area final
N36: 5 | O36: Norte | P36: =N36 -> 5 | Q36: 2.7 | R36: =P36*Q36 -> 13.5 | T36: =AD19*S36 -> 0 | U36: =R36-T36 -> 13.5
N37: 3 | P37: =N37 -> 3 | Q37: 2.7 | R37: =P37*Q37 -> 8.1 | S37: 1 | T37: =AD5*S37 -> 3 | U37: =R37-T37 -> 5.1
N38: 2 | P38: =N38 -> 2 | Q38: 2.7 | R38: =P38*Q38 -> 5.4 | T38: =S38*AD19 -> 0 | U38: =R38-T38 -> 5.4
N39: 4 | P39: =N39 -> 4 | Q39: 2.7 | R39: =P39*Q39 -> 10.8 | T39: =S39*AD13 -> 0 | U39: =R39-T39 -> 10.8
AZ42: T1 | BC42: TETO
Y43: SUL | AC43: TETO | AH43: T1 | AI43: carga | AK43: T2 | AL43: carga | AN43: T3 | AO43: carga | AQ43: T4 | AR43: carga | AT43: T5 | AU43: carga | AZ43: T2 | BD43: COMP | BE43: LAR | BF43: AREA | BG43: CARGA
C44: Parede externa Pe1 | G44: Parede externa Pe1 | K44: Parede externa Pe1 | O44: Parede externa Pe1 | S44: Parede externa Pe1 | Y44: hora | Z44: carga | AD44: COMP | AE44: LAR | AF44: AREA | AH44: 8 | AI44: =$E$11*$AF$45*AP12 -> 526.2026 | AK44: 8 | AL44: =$E$11*$AF$46*AP12 -> 135.30924 | AN44: 8 | AO44: =$E$11*$AF$47*AP12 -> 481.09952 | AQ44: 8 | AR44: =$E$11*$AF$48*AP12 -> 526.2026 | AT44: 8 | AU44: =$E$11*$AF$49*AP12 -> 180.41232 | AZ44: T3 | BC44: T1 | BD44: 5 | BE44: 7 | BF44: =BD44*BE44 -> 35 | BG44: =AI54 -> 780.6526
C45: trecho | D45: hora | E45: carga | G45: trecho | H45: hora | I45: carga | K45: trecho | L45: hora | M45: carga | O45: trecho | P45: hora | Q45: carga | S45: trecho | T45: hora | U45: carga | X45: SUL | Y45: 8 | Z45: =E46+I46+M46+Q46+U46 -> 147.2228 | AC45: T1 | AD45: 5 | AE45: 7 | AF45: =AD45*AE45 -> 35 | AH45: 9 | AI45: =$E$11*$AF$45*AP13 -> 526.2026 | AK45: 9 | AL45: =$E$11*$AF$46*AP13 -> 135.30924 | AN45: 9 | AO45: =$E$11*$AF$47*AP13 -> 481.09952 | AQ45: 9 | AR45: =$E$11*$AF$48*AP13 -> 526.2026 | AT45: 9 | AU45: =$E$11*$AF$49*AP13 -> 180.41232 | AZ45: T4 | BC45: T2 | BD45: 3 | BE45: 3 | BF45: =BD45*BE45 -> 9 | BG45: =AL54 -> 200.73924
...

Sheet Planilha6
D2: pessoas | E2: area
C3: T1 | D3: 3 | E3: =Planilha1!AF45 -> 35 | H3: Ambiente | I3: Pessoas | J3: Área (m²) | K3: Parcela Pessoas (L/s) | L3: Parcela Área (L/s) | M3: Vazão Total (L/s) | N3: Vazão Total (m³/h)
C4: T2 | D4: 3 | E4: =Planilha1!AF46 -> 9 | H4: T1 | I4: 3 | J4: 35,00 | K4: 7,5 | L4: 10,5 | M4: 18,0 | N4: 64,80
C5: T3 | D5: 0 | E5: =Planilha1!AF47 -> 32 | H5: T2 | I5: 3 | J5: 9,00 | K5: 7,5 | L5: 2,7 | M5: 10,2 | N5: 36,72
C6: T4 | D6: 8 | E6: =Planilha1!AF48 -> 35 | H6: T3 | I6: 0 | J6: 32,00 | K6: 0,0 | L6: 9,6 | M6: 9,6 | N6: 34,56
C7: T5 | D7: 1 | E7: =Planilha1!AF49 -> 12 | H7: T4 | I7: 8 | J7: 35,00 | K7: 20,0 | L7: 10,5 | M7: 30,5 | N7: 109,80
C8: T6 | D8: 4 | E8: =Planilha1!AF50 -> 15 | H8: T5 | I8: 1 | J8: 12,00 | K8: 2,5 | L8: 3,6 | M8: 6,1 | N8: 21,96
C9: T7 | D9: 2 | E9: =Planilha1!AF51 -> 12 | H9: T6 | I9: 4 | J9: 15,00 | K9: 10,0 | L9: 4,5 | M9: 14,5 | N9: 52,20
C10: T8 | D10: 6 | E10: =Planilha1!AF52 -> 25 | H10: T7 | I10: 2 | J10: 12,00 | K10: 5,0 | L10: 3,6 | M10: 8,6 | N10: 30,96
C11: T9 | D11: 3 | E11: =Planilha1!AF53 -> 9 | H11: T8 | I11: 6 | J11: 25,00 | K11: 15,0 | L11: 7,5 | M11: 22,5 | N11: 81,00
C12: T10 | D12: 8 | E12: =Planilha1!AF54 -> 32 | H12: T9 | I12: 3 | J12: 9,00 | K12: 7,5 | L12: 2,7 | M12: 10,2 | N12: 36,72
C13: T11 | D13: 24 | E13: =Planilha1!AF55 -> 460 | H13: T10 | I13: 8 | J13: 32,00 | K13: 20,0 | L13: 9,6 | M13: 29,6 | N13: 106,56
H14: T11 | I14: 24 | J14: 460,00 | K14: 60,0 | L14: 138,0 | M14: 198,0 | N14: 712,80
H15: TOTAL | I15: 62 | J15: 676,00 | K15: 155,0 | L15: 202,8 | M15: 357,8 | N15: 1288,08

Sheet Planilha5
K1: TOTAL
C2: JANELA | D2: PAREDE EXTERNA | E2: TETO | F2: PAREDE INTERNA | G2: PESSOAS | H2: ILUMINAÇÃO | I2: EQUIPAMENTO | M2: pessoas | O2: latente w | P2: sensível w
B3: T1 | C3: =Planilha4!N15 -> 412.38 | D3: =Planilha1!E56+Planilha1!I56 -> 182.8008 | E3: =Planilha1!AI54 -> 780.6526 | F3: =Planilha2!I15 -> 0 | G3: =P3 -> 3900 | H3: =E37*10 -> 350 | I3: 200 | K3: =SUM(C3:J3) -> 5825.8334 | L3: T1 | M3: 30 | N3: =M3*75 -> 2250 | O3: =M3*55 -> 1650 | P3: =N3+O3 -> 3900
B4: T2 | C4: =(Planilha4!N16)*6 -> 2474.28 | D4: =(Planilha1!Q56)*6 -> 470.0592 | E4: =(Planilha1!AL54)*6 -> 1204.4354 | F4: =(Planilha2!I7*2)*6 -> 1741.8 | G4: =P4 -> 2340 | H4: =(E38*10)*6 -> 540 | I4: =150*6 -> 900 | K4: =SUM(C4:J4) -> 9670.5746 | L4: T2 | M4: 18 | N4: =M4*75 -> 1350 | O4: =M4*55 -> 990 | P4: =N4+O4 -> 2340
B5: T3 | C5: 0 | D5: =Planilha1!U56+Planilha1!E84 -> 481.8528 | E5: =Planilha1!AO54 -> 713.73952 | F5: =Planilha2!I12 -> 72.58 | G5: 0 | H5: =E39*10 -> 320 | I5: 540 | K5: =SUM(C5:J5) -> 2128.1723 | L5: T3 | N5: =M5*75 -> 0 | O5: =M5*55 -> 0 | P5: =N5+O5 -> 0
B6: T4 | C6: =Planilha4!N23 -> 1299.78 | D6: =Planilha1!I70 -> 305.8848 | E6: =Planilha1!AR54 -> 780.6526 | F6: =Planilha2!I11 -> 169.34 | G6: 1200 | H6: =E40*10 -> 350 | I6: 200 | K6: =SUM(C6:J6) -> 4305.6574 | L6: T4 | M6: 8 | N6: =M6*75 -> 600 | O6: =M6*55 -> 440 | P6: =N6+O6 -> 1040
B7: T5 | C7: =Planilha4!N35 -> 618.57 | D7: =Planilha1!M84 -> 141.5232 | E7: =Planilha1!AU54 -> 267.65232 | F7: =Planilha2!I8 -> 145.15 | G7: 0 | H7: =E41*10 -> 120 | I7: 0 | K7: =SUM(C7:J7) -> 1292.8955 | L7: T5 | N7: =M7*75 -> 0 | O7: =M7*55 -> 0 | P7: =N7+O7 -> 0
B8: T6 | C8: =Planilha4!N26 -> 1299.78 | D8: =Planilha1!M84 -> 141.5232 | E8: =Planilha1!AI67 -> 334.5654 | F8: =Planilha2!I7 -> 145.15 | G8: =P8 -> 520 | H8: =E42*10 -> 150 | I8: 200 | K8: =SUM(C8:J8) -> 2791.0186 | L8: T6 | M8: 4 | N8: =M8*75 -> 300 | O8: =M8*55 -> 220 | P8: =N8+O8 -> 520
B9: T7 | C9: =Planilha4!N33 -> 412.38 | D9: =Planilha1!M84 -> 141.5232 | E9: =Planilha1!AL67 -> 267.65232 | F9: =Planilha2!I13 -> 72.58 | G9: 0 | H9: =E43*10 -> 120 | I9: 0 | K9: =SUM(C9:J9) -> 1014.1355 | L9: T7 | N9: =M9*75 -> 0 | O9: =M9*55 -> 0 | P9: =N9+O9 -> 0
B10: T8 | C10: =Planilha4!N28 -> 1949.67 | D10: =Planilha1!Q84+Planilha1!E98 -> 456.0192 | E10: =Planilha1!AO67 -> 557.609 | F10: =Planilha2!I10 -> 0 | G10: =P10 -> 780 | H10: =E44*10 -> 250 | I10: 500 | K10: =SUM(C10:J10) -> 4493.2982 | L10: T8 | M10: 6 | N10: =M10*75 -> 450 | O10: =M10*55 -> 330 | P10: =N10+O10 -> 780
B11: T9 | C11: =(Planilha4!N13)*7 -> 3800.16 | D11: =(Planilha1!I98)*7 -> 623.7504 | E11: =(Planilha1!AR67)*7 -> 1405.1747 | F11: =Planilha2!I10 -> 0 | G11: =P11 -> 2730 | H11: =(E45*10)*7 -> 630 | I11: =E28 -> 1050 | K11: =SUM(C11:J11) -> 10239.085 | L11: T9 | M11: 21 | N11: =M11*75 -> 1575 | O11: =M11*55 -> 1155 | P11: =N11+O11 -> 2730
B12: T10 | C12: =Planilha4!N35 -> 618.57 | D12: =Planilha1!Q84+Planilha1!Q98 -> 408.8448 | E12: =(Planilha1!AU67) -> 713.73952 | F12: =Planilha2!I14 -> 0 | G12: 1200 | H12: =E46*10 -> 320 | I12: 200 | K12: =SUM(C12:J12) -> 3461.1543 | L12: T10 | M12: 8 | N12: =M12*75 -> 600 | O12: =M12*55 -> 440 | P12: =N12+O12 -> 1040
B13: T11 | C13: 0 | D13: =Planilha1!I56+Planilha1!Q56+Planilha1!M98 -> 224.9208 | E13: =Planilha1!AX67 -> 10260.006 | F13: 0 | G13: =P13 -> 3120 | H13: =(E47*10) -> 4600 | I13: 3168 | K13: =SUM(C13:J13) -> 21372.926 | L13: T11 | M13: 24 | N13: =M13*75 -> 1800 | O13: =M13*55 -> 1320 | P13: =N13+O13 -> 3120
C14: =SUM(C3:C13) -> 12885.57 | D14: =SUM(D3:D13) -> 3578.7024 | E14: =SUM(E3:E13) -> 17285.879 | F14: =SUM(F3:F13) -> 2346.6 | G14: =SUM(G3:G13) -> 15790 | I14: =SUM(I3:I13) -> 6958 | K14: =SUM(K3:K13) -> 66594.751 | N14: total w | O14: =SUM(O3:O13) -> 6545 | P14: =SUM(P3:P13) -> 15470
B18: equipamento
C19: quantidade | D19: valor w | E19: total W
B20: T1 | C20: 1 | D20: 500 | E20: =C20*D20 -> 500
B21: T2 | C21: 1 | D21: 150 | E21: =150*6 -> 900
B22: T3 | C22: 1 | D22: 540 | E22: 540
B23: T4 | C23: 8 | D23: 150 | E23: =C23*D23 -> 1200
B24: T5 | C24: 0 | D24: 0 | E24: 0
B25: T6 | C25: 4 | D25: 150 | E25: =C25*D25 -> 600
B26: T7 | C26: 0 | D26: 0 | E26: 0
B27: T8 | C27: 1 | D27: 500 | E27: 500
B28: T9 | C28: 1 | D28: 150 | E28: =150*7 -> 1050
B29: T10 | C29: 8 | D29: 150 | E29: =C29*D29 -> 1200
B30: T11 | C30: 16 | D30: 150 | E30: =C30*D30 -> 2400
D31: total | E31: =SUM(E20:E30) -> 8890
H34: AREA | I34: ilumi W
B35: TETO | G35: T1 | H35: 35 | I35: 350
C36: COMP | D36: LAR | E36: AREA | G36: T2 | H36: 9 | I36: 540
B37: T1 | C37: 5 | D37: 7 | E37: =C37*D37 -> 35 | G37: T3 | H37: 32 | I37: 320
B38: T2 | C38: 3 | D38: 3 | E38: =C38*D38 -> 9 | G38: T4 | H38: 35 | I38: 350
B39: T3 | C39: 4 | D39: 8 | E39: =C39*D39 -> 32 | G39: T5 | H39: 12 | I39: 120
B40: T4 | C40: 5 | D40: 7 | E40: =C40*D40 -> 35 | G40: T6 | H40: 15 | I40: 150
B41: T5 | C41: 4 | D41: 3 | E41: =C41*D41 -> 12 | G41: T7 | H41: 12 | I41: 120
B42: T6 | C42: 5 | D42: 3 | E42: =C42*D42 -> 15 | G42: T8 | H42: 25 | I42: 250
B43: T7 | C43: 4 | D43: 3 | E43: =C43*D43 -> 12 | G43: T9 | H43: 9 | I43: =90*7 -> 630
B44: T8 | C44: 5 | D44: 5 | E44: =C44*D44 -> 25 | G44: T10 | H44: 32 | I44: 320
B45: T9 | C45: 3 | D45: 3 | E45: =C45*D45 -> 9 | G45: T11 | H45: 460 | I45: 4600
...

Sheet INSUFLAÇÃO
B1: w | C1: =(0.622*(C2/(C3-C2))) -> 0.018880762 | E1: w | F1: =(0.622*(F2/(F3-F2))) -> 0.0099712052 | H1: w | I1: =(0.622*(I2/(I3-I2))) -> 0.0092992419 | N1: w | O1: kg/h | P1: m³/h | Q1: kg/h | R1: kg/h | S1: QNT | T1: m³/h | U1: m³/h | V1: tamanho | W1: QNT | X1: m³/h | Y1: m³/S | Z1: m² | AA1: Tamanho | AB1: m³/s | AD1: m/s
B2: pv | C2: =2.9851 -> 2.9851 | E2: pv | F2: 1.5987 | H2: pv | I2: =0.5*I4 -> 1.49255 | M2: T1 | N2: 5825.8334 | O2: =(N2/$F$24)*$F$27 -> 2462.1137 | P2: =O2/1.2 -> 2051.7614 | Q2: =C11*27*1.2 -> 972 | R2: =O2-Q2 -> 1490.1137 | S2: 6 | T2: =P2/S2 -> 341.96024 | U2: 350 | V2: 2 | W2: 4 | X2: =R2/1.2 -> 1241.7614 | Y2: =X2/3600 -> 0.34493374 | Z2: =(Y2/2)/0.7 -> 0.24638124 | AA2: 550 x 152 | AB2: =(X2/W2)/3600 -> 0.086233434 | AC2: 0.062 | AD2: =AB2/AC2 -> 1.3908618
B3: p | C3: 101.325 | E3: p | F3: 101.325 | H3: p | I3: 101.325 | M3: T2 | N3: 9670.5746 | O3: =(N3/$F$24)*$F$27 -> 4086.9783 | P3: =O3/1.2 -> 3405.8153 | Q3: =C12*27*1.2 -> 583.2 | R3: =O3-Q3 -> 3503.7783 | S3: 6 | T3: =P3/S3 -> 567.63588 | U3: 600 | V3: 4 | W3: 6 | X3: =R3/1.2 -> 2919.8153 | Y3: =X3/3600 -> 0.81105979 | Z3: =(Y3/2)/0.7 -> 0.57932842 | AA3: 650 x 192 | AB3: =(X3/W3)/3600 -> 0.13517663 | AC3: 0.097 | AD3: =AB3/AC3 -> 1.3935735
H4: pvs | I4: 2.9851 | M4: T4 | N4: 4305.6574 | O4: =(N4/$F$24)*$F$27 -> 1819.657 | P4: =O4/1.2 -> 1516.3808 | Q4: =C13*27*1.2 -> 259.2 | R4: =O4-Q4 -> 1560.457 | S4: 4 | T4: =P4/S4 -> 379.0952 | U4: 400 | V4: 3 | W4: 2 | X4: =R4/1.2 -> 1300.3808 | Y4: =X4/3600 -> 0.36121689 | Z4: =(Y4/2)/0.7 -> 0.25801206 | AA4: 600 x 192 | AB4: =(X4/W4)/3600 -> 0.18060844 | AC4: 0.09 | AD4: =AB4/AC4 -> 2.0067605 | AE4: =SUM(AD2:AD4) -> 4.7911958
B5: ]h.externo | C5: =(1.0048+1.805*C1)*24+2501*C1 -> 72.153899 | E5: hinsuflamento | F5: =+(1.0048+1.805*F1)*14+2501*F1 -> 39.257157 | H5: h.retorno | I5: =(1.0048+1.805*I1)*24+2501*I1 -> 47.775447 | M5: T6 | N5: 2791.0186 | O5: =(N5/$J$24)*$J$27 -> 1179.5403 | P5: =O5/1.2 -> 982.95024 | Q5: =C14*27*1.2 -> 129.6 | R5: =O5-Q5 -> 1049.9403 | S5: 2 | T5: =P5/S5 -> 491.47512 | U5: 500 | V5: 4 | W5: 2 | X5: =R5/1.2 -> 874.95024 | Y5: =X5/3600 -> 0.24304173 | Z5: =(Y5/2)/0.7 -> 0.17360124 | AA5: 600 x 192 | AB5: =(X5/W5)/3600 -> 0.12152087 | AC5: 0.09 | AD5: =AB5/AC5 -> 1.3502319
M6: T9 | N6: 10239.085 | O6: =(N6/$J$24)*$J$27 -> 4327.2422 | P6: =O6/1.2 -> 3606.0352 | Q6: =C15*27*1.2 -> 680.4 | R6: =O6-Q6 -> 3646.8422 | S6: 7 | T6: =P6/S6 -> 515.14788 | U6: 500 | V6: 4 | W6: 7 | X6: =R6/1.2 -> 3039.0352 | Y6: =X6/3600 -> 0.84417643 | Z6: =(Y6/2)/0.7 -> 0.60298317 | AA6: 600 x 192 | AB6: =(X6/W6)/3600 -> 0.12059663 | AC6: 0.09 | AD6: =AB6/AC6 -> 1.3399626
M7: T10 | N7: 3461.1543 | O7: =(N7/$J$24)*$J$27 -> 1462.7531 | P7: =O7/1.2 -> 1218.9609 | Q7: =C16*27*1.2 -> 259.2 | R7: =O7-Q7 -> 1203.5531 | S7: 4 | T7: =P7/S7 -> 304.74022 | U7: 300 | V7: 2 | W7: 3 | X7: =R7/1.2 -> 1002.9609 | Y7: =X7/3600 -> 0.27860024 | Z7: =(Y7/2)/0.7 -> 0.19900017 | AA7: 600 x 152 | AB7: =(X7/W7)/3600 -> 0.092866748 | AC7: 0.067 | AD7: =AB7/AC7 -> 1.3860709
M8: T11 | N8: 21372.926 | O8: =(N8/$J$24)*$J$27 -> 9032.6263 | P8: =O8/1.2 -> 7527.1885 | Q8: =C17*27*1.2 -> 777.6 | R8: =O8-Q8 -> 8255.0263 | S8: 15 | T8: =P8/S8 -> 501.81257 | U8: 500 | V8: 3 | W8: 11 | X8: =R8/1.2 -> 6879.1885 | Y8: =X8/3600 -> 1.9108857 | Z8: =(Y8/2)/0.7 -> 1.3649184 | AA8: 650 x 252 | AB8: =(X8/W8)/3600 -> 0.17371688 | AC8: 0.134 | AD8: =AB8/AC8 -> 1.2963946
O9: insufla | Q9: Ar externo | R9: retorno | S9: DIFUSORES DE INSUFLAÇAO | W9: GRELHAS DE RETORNO | AB9: por grelha | AC9: area livre | AD9: velocidade
A10: AMBIENTE | B10: CARGA | C10: PESSOAS | D10: AREA | M10: =O2+O3+O4 -> 8368.749
A11: T1 | B11: =Planilha5!K3 -> 5825.8334 | C11: =Planilha5!M3 -> 30 | D11: =Planilha5!E37 -> 35 | N11: 2462.1137 | O11: =N11/3600 -> 0.68392048
A12: T2 | B12: =Planilha5!K4 -> 9670.5746 | C12: =Planilha5!M4 -> 18 | D12: =Planilha5!E38*6 -> 54 | N12: 4086.9783 | O12: =N12/3600 -> 1.1352718
A13: T4 | B13: =Planilha5!K6 -> 4305.6574 | C13: =Planilha5!M6 -> 8 | D13: =Planilha5!E40 -> 35 | N13: 1819.657 | O13: =N13/3600 -> 0.50546026 | Q13: 1179.5403 | R13: =Q13/3600 -> 0.32765008
A14: T6 | B14: =Planilha5!K8 -> 2791.0186 | C14: =Planilha5!M8 -> 4 | D14: =Planilha5!E42 -> 15 | N14: =SUM(N11:N13) -> 8368.749 | O14: =SUM(O11:O13) -> 2.3246525 | Q14: 4327.2422 | R14: =Q14/3600 -> 1.2020117
A15: T9 | B15: =Planilha5!K11 -> 10239.085 | C15: =Planilha5!M11 -> 21 | D15: =Planilha5!E45*7 -> 63 | Q15: 1462.7531 | R15: =Q15/3600 -> 0.40632029
A16: T10 | B16: =Planilha5!K12 -> 3461.1543 | C16: =Planilha5!M12 -> 8 | D16: =Planilha5!E46 -> 32 | Q16: 9032.6263 | R16: =Q16/3600 -> 2.5090628
A17: T11 | B17: =Planilha5!K13 -> 21372.926 | C17: =Planilha5!M13 -> 24 | D17: =Planilha5!E47 -> 460 | R17: =SUM(R13:R16) -> 4.4450449
C18: =SUM(C14:C17) -> 57 | R18: didi
F20: MAQUINA 1 | J20: MAQUINA 2
F21: GRUPO: T1 T2 T4 | J21: GRUPO: T6 T9 T10 T11
F23: CARGA TOTAL | J23: CARGA TOTAL
F24: =B11+B12+B13 -> 19802.065 | G24: W | J24: =B14+B15+B16+B17 -> 37864.184 | K24: W
F26: Mar_insuflamento | J26: Mar_insuflamento
F27: =(F24/(I5-F5))*3.6 -> 8368.749 | G27: kg/h | J27: =(J24/(I5-F5))*3.6 -> 16002.162 | K27: kg/h
F29: total serpentina | J29: total serpentina
F30: =(F27*(F55-F5))/3.6 -> 35635.974 | G30: W | J30: =(J27*(J55-F5))/3.6 -> 54571.107 | K30: W
F31: =F30/3516.85 -> 10.132924 | G31: TR | J31: =J30/3516.85 -> 15.517041 | K31: TR
F36: PESSOAS= | G36: 54 | J36: PESSOAS= | K36: 57
F37: volume ext | G37: =G36*27 -> 1458 | H37: m³\h | J37: volume ext | K37: =K36*27 -> 1539 | L37: m³\h
F38: Mexterna | G38: =G37*1.2 -> 1749.6 | H38: kg\h | J38: Mexterna | K38: =K37*1.2 -> 1846.8 | L38: kg\h
F40: Mretorno | J40: Mretorno
F41: =F27-G38 -> 6619.149 | J41: =J27-K38 -> 14155.362
F45: PR | J45: PR
F46: =F41/F27 -> 0.79093649 | J46: =J41/J27 -> 0.88459059
F48: W_mistura | J48: W_mistura
F49: =(F46*I1)+((1-F46)*C1) -> 0.011302388 | J49: =(J46*I1)+((1-J46)*C1) -> 0.010405039
F51: Tmistura | J51: Tmistura
F52: =(F46*24)+((1-F46)*32) -> 25.672508 | G52: c | J52: =(J46*24)+((1-J46)*32) -> 24.923275 | K52: c
F54: h_mistura | J54: h_mistura
F55: =(1.0048+1.805*F49)*F52+(2501*F49) -> 54.586748 | G55: KJ/KG | J55: =(1.0048+1.805*J49)*J52+(2501*J49) -> 51.533997 | K55: KJ/KG

Sheet INSUFLAÇÃO - S e T
B1: w | C1: =(0.622*(C2/(C3-C2))) -> 0.018880762 | E1: w | F1: =(0.622*(F2/(F3-F2))) -> 0.0099712052 | H1: w | I1: =(0.622*(I2/(I3-I2))) -> 0.0092992419 | N1: kg/h | O1: m³/h | P1: kg/h | Q1: kg/h | R1: qnt | U1: tamnho | V1: QNT | W1: m³/h | X1: m³/S | Y1: m² | Z1: Tamanho | AA1: m³/s | AC1: m/s
B2: pv | C2: =2.9851 -> 2.9851 | E2: pv | F2: 1.5987 | H2: pv | I2: =0.5*I4 -> 1.49255 | L2: T1 | M2: 5045.1808 | N2: =(M2/$F$24)*$F$27 -> 2132.1943 | O2: =N2/1.2 -> 1776.8286 | P2: =C11*27*1.2 -> 972 | Q2: =N2-P2 -> 1160.1943 | R2: 4 | S2: =O2/R2 -> 444.20715 | T2: 450 | U2: 3 | V2: 4 | W2: =Q2/1.2 -> 966.82861 | X2: =W2/3600 -> 0.2685635 | Y2: =(X2/2)/0.7 -> 0.19183107 | Z2: 550 x 152 | AA2: =(W2/V2)/3600 -> 0.067140876 | AB2: 0.062 | AC2: =AA2/AB2 -> 1.0829174
B3: p | C3: 101.325 | E3: p | F3: 101.325 | H3: p | I3: 101.325 | L3: T2 | M3: 8466.1392 | N3: =(M3/$F$24)*$F$27 -> 3577.9598 | O3: =N3/1.2 -> 2981.6332 | P3: =C12*27*1.2 -> 583.2 | Q3: =N3-P3 -> 2994.7598 | R3: 6 | S3: =O3/R3 -> 496.93886 | T3: 500 | U3: 3 | V3: 6 | W3: =Q3/1.2 -> 2495.6332 | X3: =W3/3600 -> 0.69323143 | Y3: =(X3/2)/0.7 -> 0.49516531 | Z3: 650 x 192 | AA3: =(W3/V3)/3600 -> 0.11553857 | AB3: 0.097 | AC3: =AA3/AB3 -> 1.1911193
H4: pvs | I4: 2.9851 | L4: T4 | M4: 3525.0048 | N4: =(M4/$F$24)*$F$27 -> 1489.7375 | O4: =N4/1.2 -> 1241.448 | P4: =C13*27*1.2 -> 259.2 | Q4: =N4-P4 -> 1230.5375 | R4: 4 | S4: =O4/R4 -> 310.36199 | T4: 300 | U4: 3 | V4: 2 | W4: =Q4/1.2 -> 1025.448 | X4: =W4/3600 -> 0.28484665 | Y4: =(X4/2)/0.7 -> 0.2034619 | Z4: 600 x 192 | AA4: =(W4/V4)/3600 -> 0.14242333 | AB4: 0.09 | AC4: =AA4/AB4 -> 1.5824814
B5: ]h.externo | C5: =(1.0048+1.805*C1)*24+2501*C1 -> 72.153899 | E5: hinsuflamento | F5: =+(1.0048+1.805*F1)*14+2501*F1 -> 39.257157 | H5: h.retorno | I5: =(1.0048+1.805*I1)*24+2501*I1 -> 47.775447 | L5: T6 | M5: 2456.4532 | N5: =(M5/$J$24)*$J$27 -> 1038.1463 | O5: =N5/1.2 -> 865.12189 | P5: =C14*27*1.2 -> 129.6 | Q5: =N5-P5 -> 908.54626 | R5: 2 | S5: =O5/R5 -> 432.56094 | T5: 450 | U5: 3 | V5: 2 | W5: =Q5/1.2 -> 757.12189 | X5: =W5/3600 -> 0.21031163 | Y5: =(X5/2)/0.7 -> 0.1502226 | Z5: 600 x 192 | AA5: =(W5/V5)/3600 -> 0.10515582 | AB5: 0.09 | AC5: =AA5/AB5 -> 1.168398
L6: T9 | M6: 8833.9104 | N6: =(M6/$J$24)*$J$27 -> 3733.3873 | O6: =N6/1.2 -> 3111.156 | P6: =C15*27*1.2 -> 680.4 | Q6: =N6-P6 -> 3052.9873 | R6: 7 | S6: =O6/R6 -> 444.45086 | T6: 450 | U6: 3 | V6: 7 | W6: =Q6/1.2 -> 2544.156 | X6: =W6/3600 -> 0.70671001 | Y6: =(X6/2)/0.7 -> 0.50479287 | Z6: 600 x 192 | AA6: =(W6/V6)/3600 -> 0.10095857 | AB6: 0.09 | AC6: =AA6/AB6 -> 1.1217619
L7: T10 | M7: 2747.4148 | N7: =(M7/$J$24)*$J$27 -> 1161.1125 | O7: =N7/1.2 -> 967.59371 | P7: =C16*27*1.2 -> 259.2 | Q7: =N7-P7 -> 901.91246 | R7: 4 | S7: =O7/R7 -> 241.89843 | T7: 250 | U7: 1 | V7: 3 | W7: =Q7/1.2 -> 751.59371 | X7: =W7/3600 -> 0.20877603 | Y7: =(X7/2)/0.7 -> 0.14912574 | Z7: 600 x 152 | AA7: =(W7/V7)/3600 -> 0.06959201 | AB7: 0.067 | AC7: =AA7/AB7 -> 1.0386867
L8: T11 | M8: 11112.921 | N8: =(M8/$J$24)*$J$27 -> 4696.5426 | O8: =N8/1.2 -> 3913.7855 | P8: =C17*27*1.2 -> 777.6 | Q8: =N8-P8 -> 3918.9426 | R8: 13 | S8: =O8/R8 -> 301.06043 | T8: 300 | U8: 2 | V8: 11 | W8: =Q8/1.2 -> 3265.7855 | X8: =W8/3600 -> 0.90716265 | Y8: =(X8/2)/0.7 -> 0.64797332 | Z8: 650 x 252 | AA8: =(W8/V8)/3600 -> 0.082469332 | AB8: 0.134 | AC8: =AA8/AB8 -> 0.61544277
N9: insufla | P9: Ar externo | Q9: retorno | V9: GRELHAS DE RETORNO | AA9: por grelha | AB9: area livre | AC9: velocidade
A10: AMBIENTE | B10: CARGA | C10: PESSOAS | D10: AREA
A11: T1 | B11: =Planilha5!L84 -> 5045.1808 | C11: =Planilha5!M3 -> 30 | D11: =Planilha5!E37 -> 35
A12: T2 | B12: =Planilha5!L85 -> 8466.1392 | C12: =Planilha5!M4 -> 18 | D12: =Planilha5!E38*6 -> 54
A13: T4 | B13: =Planilha5!L87 -> 3525.0048 | C13: =Planilha5!M6 -> 8 | D13: =Planilha5!E40 -> 35
A14: T6 | B14: =Planilha5!L89 -> 2456.4532 | C14: =Planilha5!M8 -> 4 | D14: =Planilha5!E42 -> 15
A15: T9 | B15: =Planilha5!L92 -> 8833.9104 | C15: =Planilha5!M11 -> 21 | D15: =Planilha5!E45*7 -> 63
A16: T10 | B16: =Planilha5!L93 -> 2747.4148 | C16: =Planilha5!M12 -> 8 | D16: =Planilha5!E46 -> 32
A17: T11 | B17: =Planilha5!L94 -> 11112.921 | C17: =Planilha5!M13 -> 24 | D17: =Planilha5!E47 -> 460
C18: =SUM(C14:C17) -> 57
F20: MAQUINA 1 | J20: MAQUINA 2
F21: GRUPO: T1 T2 T4 | J21: GRUPO: T6 T9 T10 T11
F23: CARGA TOTAL | J23: CARGA TOTAL
F24: =B11+B12+B13 -> 17036.325 | G24: W | J24: =B14+B15+B16+B17 -> 25150.699 | K24: W
F26: Mar_insuflamento | J26: Mar_insuflamento
F27: =(F24/(I5-F5))*3.6 -> 7199.8917 | G27: kg/h | J27: =(J24/(I5-F5))*3.6 -> 10629.189 | K27: kg/h
F29: total serpentina | J29: total serpentina
F30: =(F27*(F55-F5))/3.6 -> 32872.515 | G30: W | J30: =(J27*(J55-F5))/3.6 -> 41861.763 | K30: W
F31: =F30/3516.85 -> 9.3471474 | G31: TR | J31: =J30/3516.85 -> 11.903198 | K31: TR
F36: PESSOAS= | G36: 54 | J36: PESSOAS= | K36: 57
F37: volume ext | G37: =G36*27 -> 1458 | H37: m³\h | J37: volume ext | K37: =K36*27 -> 1539 | L37: m³\h
F38: Mexterna | G38: =G37*1.2 -> 1749.6 | H38: kg\h | J38: Mexterna | K38: =K37*1.2 -> 1846.8 | L38: kg\h
F40: Mretorno | J40: Mretorno
F41: =F27-G38 -> 5450.2917 | J41: =J27-K38 -> 8782.3886
F45: PR | J45: PR
F46: =F41/F27 -> 0.75699634 | J46: =J41/J27 -> 0.82625202
F48: W_mistura | J48: W_mistura
F49: =(F46*I1)+((1-F46)*C1) -> 0.011627586 | J49: =(J46*I1)+((1-J46)*C1) -> 0.010964012
F51: Tmistura | J51: Tmistura
F52: =(F46*24)+((1-F46)*32) -> 25.944029 | G52: c | J52: =(J46*24)+((1-J46)*32) -> 25.389984 | K52: c
F54: h_mistura | J54: h_mistura
F55: =(1.0048+1.805*F49)*F52+(2501*F49) -> 55.693662 | G55: KJ/KG | J55: =(1.0048+1.805*J49)*J52+(2501*J49) -> 53.435317 | K55: KJ/KG

Sheet Planilha4
A2: PME3515 – CÁLCULO DE CARGA TÉRMICA DE VIDROS (Equações 12, 13, 14, 15)
A3: CT_vidros(h) = CT_vidros,condução(h) + CT_vidros,radiação(h) | CT_condução = Uv × Av × DTCTvidros | CT_radiação = Av × CS × GCS × FCT | DTCTvidros = [(DTCTtab + LM) + (25,5 – Ti) + (Tm – 29,4)]
A4: IDENTIFICAÇÃO | C4: GEOMETRIA (m) | E4: ORIENT. | F4: PARÂMETROS | J4: CT CONDUÇÃO (Eq.13) | L4: CT RADIAÇÃO (Eq.15) | N4: TOTAL (Eq.12)
A5: ID | B5: Zona / Ambiente | C5: L (m) | D5: H (m) | E5: Orient. | F5: Av (m²) | G5: Uv (W/m²°C) | H5: DTCT vidros (°C) | I5: CS (–) | J5: GCS (W/m²) | K5: FCT (–) | L5: CT_cond (W) | M5: CT_rad (W) | N5: CT_total (W)
A6: ▶ FACHADA NORTE
A7: J-N01 | B7: 1N – Perímetro Norte | C7: 2 | D7: 1.5 | E7: Norte | F7: 3 | G7: 5.8 | H7: 7.2 | I7: 0.87 | J7: 160 | K7: 1 | L7: 125.28 | M7: 417.6 | N7: 542.88
A8: J-N02 | B8: 1N – Perímetro Norte | C8: 2 | D8: 1.5 | E8: Norte | F8: 3 | G8: 5.8 | H8: 7.2 | I8: 0.87 | J8: 160 | K8: 1 | L8: 125.28 | M8: 417.6 | N8: 542.88
A9: J-N03 | B9: 1N – Perímetro Norte | C9: 2 | D9: 1.5 | E9: Norte | F9: 3 | G9: 5.8 | H9: 7.2 | I9: 0.87 | J9: 160 | K9: 1 | L9: 125.28 | M9: 417.6 | N9: 542.88
A10: J-N04 | B10: 1N – Perímetro Norte | C10: 2 | D10: 1.5 | E10: Norte | F10: 3 | G10: 5.8 | H10: 7.2 | I10: 0.87 | J10: 160 | K10: 1 | L10: 125.28 | M10: 417.6 | N10: 542.88
A11: J-N05 | B11: 1N – Perímetro Norte | C11: 2 | D11: 1.5 | E11: Norte | F11: 3 | G11: 5.8 | H11: 7.2 | I11: 0.87 | J11: 160 | K11: 1 | L11: 125.28 | M11: 417.6 | N11: 542.88
A12: J-N06 | B12: 1N – Perímetro Norte | C12: 2 | D12: 1.5 | E12: Norte | F12: 3 | G12: 5.8 | H12: 7.2 | I12: 0.87 | J12: 160 | K12: 1 | L12: 125.28 | M12: 417.6 | N12: 542.88
A13: J-N07 | B13: 1N – Perímetro Norte | C13: 2 | D13: 1.5 | E13: Norte | F13: 3 | G13: 5.8 | H13: 7.2 | I13: 0.87 | J13: 160 | K13: 1 | L13: 125.28 | M13: 417.6 | N13: 542.88
A14: ▶ FACHADA SUL
A15: J-S01 | B15: 1S – Perímetro Sul | C15: 2 | D15: 1.5 | E15: Sul | F15: 3 | G15: 5.8 | H15: 7.2 | I15: 0.87 | J15: 110 | K15: 1 | L15: 125.28 | M15: 287.1 | N15: 412.38
A16: J-S02 | B16: 1S – Perímetro Sul | C16: 2 | D16: 1.5 | E16: Sul | F16: 3 | G16: 5.8 | H16: 7.2 | I16: 0.87 | J16: 110 | K16: 1 | L16: 125.28 | M16: 287.1 | N16: 412.38
A17: J-S03 | B17: 1S – Perímetro Sul | C17: 2 | D17: 1.5 | E17: Sul | F17: 3 | G17: 5.8 | H17: 7.2 | I17: 0.87 | J17: 110 | K17: 1 | L17: 125.28 | M17: 287.1 | N17: 412.38
A18: J-S04 | B18: 1S – Perímetro Sul | C18: 2 | D18: 1.5 | E18: Sul | F18: 3 | G18: 5.8 | H18: 7.2 | I18: 0.87 | J18: 110 | K18: 1 | L18: 125.28 | M18: 287.1 | N18: 412.38
A19: J-S05 | B19: 1S – Perímetro Sul | C19: 2 | D19: 1.5 | E19: Sul | F19: 3 | G19: 5.8 | H19: 7.2 | I19: 0.87 | J19: 110 | K19: 1 | L19: 125.28 | M19: 287.1 | N19: 412.38
A20: J-S06 | B20: 6 – Copa | C20: 2 | D20: 1.5 | E20: Sul | F20: 3 | G20: 5.8 | H20: 7.2 | I20: 0.87 | J20: 110 | K20: 1 | L20: 125.28 | M20: 287.1 | N20: 412.38
A21: J-S07 | B21: 6 – Copa | C21: 2 | D21: 1.5 | E21: Sul | F21: 3 | G21: 5.8 | H21: 7.2 | I21: 0.87 | J21: 110 | K21: 1 | L21: 125.28 | M21: 287.1 | N21: 412.38
A22: ▶ FACHADA OESTE
A23: J-O01 | B23: 5 – Auditório | C23: 2 | D23: 1.5 | E23: Oeste | F23: 3 | G23: 5.8 | H23: 7.2 | I23: 0.87 | J23: 450 | K23: 1 | L23: 125.28 | M23: 1174.5 | N23: 1299.78
A24: J-O02 | B24: 5 – Auditório | C24: 2 | D24: 1.5 | E24: Oeste | F24: 3 | G24: 5.8 | H24: 7.2 | I24: 0.87 | J24: 450 | K24: 1 | L24: 125.28 | M24: 1174.5 | N24: 1299.78
A25: J-O03 | B25: 5 – Auditório | C25: 2 | D25: 1.5 | E25: Oeste | F25: 3 | G25: 5.8 | H25: 7.2 | I25: 0.87 | J25: 450 | K25: 1 | L25: 125.28 | M25: 1174.5 | N25: 1299.78
A26: J-O04 | B26: 1O – Perímetro Oeste | C26: 2 | D26: 1.5 | E26: Oeste | F26: 3 | G26: 5.8 | H26: 7.2 | I26: 0.87 | J26: 450 | K26: 1 | L26: 125.28 | M26: 1174.5 | N26: 1299.78
A27: J-O05 | B27: 1O – Perímetro Oeste | C27: 2 | D27: 1.5 | E27: Oeste | F27: 3 | G27: 5.8 | H27: 7.2 | I27: 0.87 | J27: 450 | K27: 1 | L27: 125.28 | M27: 1174.5 | N27: 1299.78
A28: J-O06 | B28: 6 – Copa | C28: 3 | D28: 1.5 | E28: Oeste | F28: 4.5 | G28: 5.8 | H28: 7.2 | I28: 0.87 | J28: 450 | K28: 1 | L28: 187.92 | M28: 1761.75 | N28: 1949.67
A29: ▶ FACHADA LESTE
A30: J-L01 | B30: 2 – Sala de Máquinas | C30: 3 | D30: 1.5 | E30: Leste | F30: 4.5 | G30: 5.8 | H30: 7.2 | I30: 0.87 | J30: 110 | K30: 1 | L30: 187.92 | M30: 430.65 | N30: 618.57
A31: J-L02 | B31: 2 – Sala de Máquinas | C31: 3 | D31: 1.5 | E31: Leste | F31: 4.5 | G31: 5.8 | H31: 7.2 | I31: 0.87 | J31: 110 | K31: 1 | L31: 187.92 | M31: 430.65 | N31: 618.57
A32: J-L03 | B32: 2 – Sala de Máquinas | C32: 3 | D32: 1.5 | E32: Leste | F32: 4.5 | G32: 5.8 | H32: 7.2 | I32: 0.87 | J32: 110 | K32: 1 | L32: 187.92 | M32: 430.65 | N32: 618.57
A33: J-L04 | B33: 4 – Sala de Reunião | C33: 2 | D33: 1.5 | E33: Leste | F33: 3 | G33: 5.8 | H33: 7.2 | I33: 0.87 | J33: 110 | K33: 1 | L33: 125.28 | M33: 287.1 | N33: 412.38
A34: J-L05 | B34: 4 – Sala de Reunião | C34: 2 | D34: 1.5 | E34: Leste | F34: 3 | G34: 5.8 | H34: 7.2 | I34: 0.87 | J34: 110 | K34: 1 | L34: 125.28 | M34: 287.1 | N34: 412.38
A35: J-L06 | B35: 4 – Sala de Reunião | C35: 3 | D35: 1.5 | E35: Leste | F35: 4.5 | G35: 5.8 | H35: 7.2 | I35: 0.87 | J35: 110 | K35: 1 | L35: 187.92 | M35: 430.65 | N35: 618.57
A36: ▶ FACHADA NORTE
A37: J-N08 | B37: 5 – Auditório | C37: 2 | D37: 1.5 | E37: Norte | F37: 3 | G37: 5.8 | H37: 7.2 | I37: 0.87 | J37: 160 | K37: 1 | L37: 125.28 | M37: 417.6 | N37: 542.88

Sheet Planilha2
A1: PME3515 – CÁLCULO DE CARGA TÉRMICA DE PAREDES INTERNAS (ASHRAE Handbook Fundamentals)
A2: CT_parede_int = U × Ap × ΔT_adj | ASHRAE: Parede adj. a espaço não condicionado → ΔT = Tunc – Ti = ½ × ΔText ≈ 4,0°C | Parede entre zonas condicionadas (mesma Tset) → ΔT = 0 (sem carga líquida)
A3: FUNDAMENTO (ASHRAE HF Cap.18): A carga de resfriamento por paredes internas só existe quando o ambiente adjacente NÃO é condicionado (banheiros, áreas técnicas não resfriadas, halls). Para ambientes condicionados com a mesma temperatura de setpoint, ΔT = 0 e CT = 0.
A4: ID | B4: Parede / Divisória | C4: Separa (de → para) | D4: Larg (m) | E4: Alt (m) | F4: Ap (m²) | G4: U (W/m²°C) | H4: ΔT_adj (°C) | I4: CT_parede (W) | J4: Observação
A5: PI-01 | B5: Zona 1 (Esc.) ↔ Zona 5 (Audit.) | C5: Z1 → Z5 | D5: 5 | E5: 2.7 | F5: 13.5 | G5: 2.24 | H5: 0 | I5: 0 | J5: Ambas condicionadas – mesma Tset → CT = 0 (ASHRAE HF §18.1)
A6: PI-02 | B6: Zona 1 (Esc.) ↔ Zona 2 (S.Maq.) | C6: Z1 → Z2 | D6: 8 | E6: 2.7 | F6: 21.6 | G6: 2.24 | H6: 0 | I6: 0 | J6: Ambas condicionadas – ΔT = 0
A7: PI-03 | B7: Zona 1 (Esc.) ↔ Zona 3 (Banh.) | C7: Z1 → Z3 (não-cond.) | D7: 6 | E7: 2.7 | F7: 16.2 | G7: 2.24 | H7: 4 | I7: 145.15 | J7: Banheiro sem AC – Tunc ≈ Ti + ½ΔText ≈ 28°C → ΔT = 4°C
A8: PI-03b | B8: Zona 3b (2º banh.) ↔ Zona 1 | C8: Z3b → Z1 | D8: 6 | E8: 2.7 | F8: 16.2 | G8: 2.24 | H8: 4 | I8: 145.15 | J8: Segundo banheiro – mesmo critério
A9: PI-04 | B9: Zona 1 (Esc.) ↔ Zona 4 (S.Reun.) | C9: Z1 → Z4 | D9: 8 | E9: 2.7 | F9: 21.6 | G9: 2.24 | H9: 0 | I9: 0 | J9: Ambas condicionadas – ΔT = 0
A10: PI-05 | B10: Zona 1 (Esc.) ↔ Zona 6 (Copa) | C10: Z1 → Z6 | D10: 8 | E10: 2.7 | F10: 21.6 | G10: 2.24 | H10: 0 | I10: 0 | J10: Ambas condicionadas – ΔT = 0
A11: PI-06 | B11: Zona 5 (Audit.) ↔ hall Norte | C11: Z5 → Hall | D11: 7 | E11: 2.7 | F11: 18.9 | G11: 2.24 | H11: 4 | I11: 169.34 | J11: Hall/corredor não condicionado – ΔT = 4°C
A12: PI-07 | B12: Zona 2 (S.Maq.) ↔ Zona 3 (Banh.) | C12: Z2 → Z3 | D12: 3 | E12: 2.7 | F12: 8.1 | G12: 2.24 | H12: 4 | I12: 72.58 | J12: Z3 não condicionado – ΔT = 4°C (incide em Z2)
A13: PI-08 | B13: Zona 3 (Banh.) ↔ Zona 4 (S.Reun.) | C13: Z3 → Z4 | D13: 3 | E13: 2.7 | F13: 8.1 | G13: 2.24 | H13: 4 | I13: 72.58 | J13: Z3 não condicionado – ΔT = 4°C (incide em Z4)
A14: PI-09 | B14: Zona 4 (S.Reun.) ↔ Zona 2 (S.Maq.) | C14: Z4 → Z2 | D14: 8 | E14: 2.7 | F14: 21.6 | G14: 2.24 | H14: 0 | I14: 0 | J14: Ambas condicionadas – ΔT = 0
A15: PI-10 | B15: Zona 5 (Audit.) ↔ Zona 6 (Copa) | C15: Z5 → Z6 | D15: 3 | E15: 2.7 | F15: 8.1 | G15: 2.24 | H15: 0 | I15: 0 | J15: Ambas condicionadas – ΔT = 0
A16: PI-11 | B16: Zona 1C (Miolo) ↔ Zona 1N | C16: Z1C → Z1N | D16: 22 | E16: 2.7 | F16: 59.4 | G16: 2.24 | H16: 0 | I16: 0 | J16: Zonas com mesma Tset – sem carga líquida (ASHRAE)
... A18: PI-13 | B18: Zona 1C (Miolo) ↔ Zona 1O | C18: Z1C → Z1O | D18: 14 | E18: 2.7 | F18: 37.8 | G18: 2.24 | H18: 0 | I18: 0 | J18: Zonas com mesma Tset – sem carga líquida
